Workbook

Sheet Assumptions
A1: Helix Biotech — Series B model inputs | B1: Value
A3: Pre-money valuation | B3: 112000000
A4: Primary proceeds (total) | B4: 28000000
A5: Post-money (before pool refresh) | B5: 140000000
A6: Calendar-quarter TTM rollup (2024-Q1:Q4) | B6: ='Cohort Build'!B23 -> 40359060
A7: Pending renewal excluded (Apex Diagnostics) | B7: 2252680
A8: Model ARR (TTM, normalized per Footnote 1) | B8: ='Cohort Build'!B24 -> 38106380
A9: Model NTM ARR (Y1 / 28% growth per Footnote 3) | B9: ='Revenue Forecast'!C3 -> 48776167
A10: Brief headline run-rate (not used for model) | B10: 42100000
A11: Series B price per share | B11: =B3/B12 -> 6.6565
A12: FD shares pre-money (cap_table.csv total) | B12: 16825600
A13: FD shares mid (pre-pool refresh) | B13: =B12+B19+B20+B21+B22 -> 22502116
A14: Founders/employees FD subtotal (cap_table.csv) | B14: 10325600
A15: Forsyth Equity Series A shares | B15: 6500000
A16: Forsyth Equity Series A price | B16: 1.82
A17: Vesper Growth SAFE invested | B17: 2500000
A18: Quorum Ventures SAFE invested | B18: 1750000
A19: Vesper Growth SAFE conversion shares | B19: =ROUND(B17/B43,0) -> 934756
A20: Quorum Ventures SAFE conversion shares | B20: =ROUND(B18/(55000000/B12),0) -> 535360
A21: Forsyth Equity Series B pro-rata shares | B21: =ROUND((B4*B15/B12)/B11,0) -> 1625000
A22: Octavian Capital Series B lead shares | B22: =ROUND((B4-B4*B15/B12)/B11,0) -> 2581400
A23: Existing stock-plan option pool (allocated Options rows) | B23: 1942000
A24: Option pool refresh shares (15% board case) | B24: ='Option pool cases'!D3 -> 1686256
A25: Option pool refresh shares (12% counsel case) | B25: ='Option pool cases'!D2 -> 861652
A26: Post-money option pool target | B26: 0.15
A27: Counsel side-letter pool reference | B27: 0.12
A28: Vesper Growth MFN clause | B28: Outstanding / unresolved per cap_table.csv and investor_brief.txt; no separately confirmed alternative MFN term in the source materials
A29: Vesper Growth conversion treatment | B29: Vesper Growth SAFE is modeled at the valuation-cap price for the base case because the $45.0M cap price is below the 20%-discounted Series B price. The MFN remains an outstanding diligence item and is not treated as cleared.
A30: FCF margin (Footnote 3) | B30: 0.22
A31: NTM multiple — low | B31: 5.5
A32: NTM multiple — high | B32: 7
A33: TTM downside multiple | B33: 5
A34: Peer median NTM multiple (sensitivity) | B34: 6.1
A35: Trailing cohort NRR diagnostic (not stacked onto Footnote 3 total growth) | B35: 1.08
A36: DCF WACC low (high-EV case) | B36: 0.14
A37: DCF WACC high (low-EV case) | B37: 0.16
A38: Terminal growth | B38: 0.03
A39: Y1 total ARR growth (Footnote 3 — total path, not additive to absolute NRR) | B39: 0.28
A40: Post-money FD shares (15% pool case) | B40: ='Option pool cases'!E3 -> 24188372
A41: Vesper Growth valuation-cap price | B41: =45000000/B12 -> 2.6745
...

Sheet Cohort Build
A1: cohort_vintage | B1: calendar_quarter | C1: starting_arr | D1: gross_retention_pct | E1: expansion_arr | F1: churn_arr | G1: ending_arr | H1: include_flag | I1: exclusion_reason | J1: source_notes
A2: FY2023-Q3 | B2: 2024-Q1 | C2: 3827400 | D2: 95.4 | E2: 198700 | F2: 61300 | G2: =C2*D2/100+E2-F2 -> 3788739.6 | H2: 1 | I2: RETAINED — unique 2024 calendar-quarter cohort record | J2: cohort_summary.xlsx Cohort Detail
A3: FY2023-Q4 | B3: 2024-Q1 | C3: 4218600 | D3: 95.7 | E3: 246800 | F3: 55900 | G3: =C3*D3/100+E3-F3 -> 4228100.2 | H3: 1 | I3: RETAINED — unique 2024 calendar-quarter cohort record | J3: cohort_summary.xlsx Cohort Detail
A4: FY2023-Q4 | B4: 2024-Q2 | C4: 4409300 | D4: 94.8 | E4: 231400 | F4: 72600 | G4: =C4*D4/100+E4-F4 -> 4338816.4 | H4: 1 | I4: RETAINED — unique 2024 calendar-quarter cohort record | J4: cohort_summary.xlsx Cohort Detail
A5: FY2024-Q1 | B5: 2024-Q2 | C5: 4886200 | D5: 96.3 | E5: 284700 | F5: 48500 | G5: =C5*D5/100+E5-F5 -> 4941610.6 | H5: 1 | I5: RETAINED — unique 2024 calendar-quarter cohort record | J5: cohort_summary.xlsx Cohort Detail
A6: FY2024-Q1 | B6: 2024-Q3 | C6: 5122600 | D6: 95.9 | E6: 256400 | F6: 63800 | G6: =C6*D6/100+E6-F6 -> 5105173.4 | H6: 1 | I6: RETAINED — unique 2024 calendar-quarter cohort record | J6: cohort_summary.xlsx Cohort Detail
A7: FY2024-Q2 | B7: 2024-Q3 | C7: 5684300 | D7: 95.2 | E7: 312900 | F7: 81400 | G7: =C7*D7/100+E7-F7 -> 5642953.6 | H7: 1 | I7: RETAINED — unique 2024 calendar-quarter cohort record | J7: cohort_summary.xlsx Cohort Detail
A8: FY2024-Q2 | B8: 2024-Q4 | C8: 5915800 | D8: 94.7 | E8: 298600 | F8: 94200 | G8: =C8*D8/100+E8-F8 -> 5806662.6 | H8: 1 | I8: RETAINED — unique 2024 calendar-quarter cohort record | J8: cohort_summary.xlsx Cohort Detail
A9: FY2024-Q3 | B9: 2024-Q4 | C9: 6482400 | D9: 96 | E9: 341200 | F9: 57300 | G9: =C9*D9/100+E9-F9 -> 6507004 | H9: 1 | I9: RETAINED — unique 2024 calendar-quarter cohort record | J9: Includes Apex Diagnostics pending enterprise renewal $2,252,680 ARR — contract out for signature, expected 2024-12-18
A10: FY2023-Q2 | B10: 2023-Q4 | C10: 3252700 | D10: 95.3 | E10: 178600 | F10: 0 | G10: =C10*D10/100+E10-F10 -> 3278423.1 | H10: 0 | I10: EXCLUDED — duplicate FY2023-Q2 expansion already captured on prior line | J10: DUPLICATE ROW — expansion already captured on prior line
A12: Inventory control
A13: raw_source_rows_in_inventory | B13: =COUNTA(A2:A10) -> 9
A14: excluded_duplicate_rows | B14: =COUNTIF(H2:H10,0) -> 1
A15: retained_rows_for_normalized_ARR | B15: =SUM(H2:H10) -> 8
A16: retention_formula | B16: ending_arr = starting×gross_retention%/100 + expansion − churn (gross_retention is before expansion/churn; churn counted once)
A18: calendar_quarter | B18: rollup_arr_from_retained_rows | C18: source
A19: 2024-Q1 | B19: =SUMIFS(G$2:G$10,B$2:B$10,A19,H$2:H$10,1) -> 8016839.8 | C19: SUMIFS of retained Cohort Detail ending_arr (reconciles to Quarterly Rollup)
A20: 2024-Q2 | B20: =SUMIFS(G$2:G$10,B$2:B$10,A20,H$2:H$10,1) -> 9280427 | C20: SUMIFS of retained Cohort Detail ending_arr (reconciles to Quarterly Rollup)
A21: 2024-Q3 | B21: =SUMIFS(G$2:G$10,B$2:B$10,A21,H$2:H$10,1) -> 10748127 | C21: SUMIFS of retained Cohort Detail ending_arr (reconciles to Quarterly Rollup)
A22: 2024-Q4 | B22: =SUMIFS(G$2:G$10,B$2:B$10,A22,H$2:H$10,1) -> 12313667 | C22: SUMIFS of retained Cohort Detail ending_arr (reconciles to Quarterly Rollup)
A23: TTM rollup sum (2024 quarters) | B23: =SUM(B19:B22) -> 40359060
A24: Normalized model ARR (ex pending renewal) | B24: =B23-Assumptions!B7 -> 38106380

Sheet Revenue Forecast
A1: Year | B1: Growth rate (total ARR path) | C1: ARR | D1: FCF margin | E1: Free cash flow | F1: Driver notes
A2: Base (normalized TTM) | B2: 0 | C2: =Assumptions!B8 -> 38106380 | D2: =Assumptions!B30 -> 0.22 | E2: =C2*D2 -> 8383403.7 | F2: From Cohort Build normalized TTM (formula-linked)
A3: Y1 | B3: =Assumptions!B39 -> 0.28 | C3: =C2*Assumptions!B46*(1+B3) -> 48776167 | D3: =Assumptions!B30 -> 0.22 | E3: =C3*D3 -> 10730757 | F3: Normalized TTM × retention stress scalar (Assumptions!B46, base 1.00) × (1 + Y1 total ARR growth). Absolute NRR is not re-applied.
A4: Y2 | B4: 0.24 | C4: =C3*(1+B4) -> 60482447 | D4: =Assumptions!B30 -> 0.22 | E4: =C4*D4 -> 13306138 | F4: Footnote 3 forward path on prior-year ARR
A5: Y3 | B5: 0.2 | C5: =C4*(1+B5) -> 72578936 | D5: =Assumptions!B30 -> 0.22 | E5: =C5*D5 -> 15967366 | F5: Footnote 3 forward path on prior-year ARR
A6: Y4 | B6: 0.16 | C6: =C5*(1+B6) -> 84191566 | D6: =Assumptions!B30 -> 0.22 | E6: =C6*D6 -> 18522145 | F6: Footnote 3 forward path on prior-year ARR
A7: Y5 | B7: 0.14 | C7: =C6*(1+B7) -> 95978385 | D7: =Assumptions!B30 -> 0.22 | E7: =C7*D7 -> 21115245 | F7: Footnote 3 forward path on prior-year ARR

Sheet DCF Build
A1: year | B1: arr | C1: fcf | D1: df_14pct | E1: pv_14pct | F1: df_16pct | G1: pv_16pct | I1: WACC high-EV case | J1: =Assumptions!B36 -> 0.14
A2: 1 | B2: ='Revenue Forecast'!C3 -> 48776167 | C2: =B2*$J$3 -> 10730757 | D2: =1/(1+$J$1)^A2 -> 0.87719298 | E2: =C2*D2 -> 9412944.5 | F2: =1/(1+$J$2)^A2 -> 0.86206897 | G2: =C2*F2 -> 9250652.3 | I2: WACC low-EV case | J2: =Assumptions!B37 -> 0.16
A3: 2 | B3: ='Revenue Forecast'!C4 -> 60482447 | C3: =B3*$J$3 -> 13306138 | D3: =1/(1+$J$1)^A3 -> 0.76946753 | E3: =C3*D3 -> 10238641 | F3: =1/(1+$J$2)^A3 -> 0.7431629 | G3: =C3*F3 -> 9888628.4 | I3: FCF margin | J3: =Assumptions!B30 -> 0.22
A4: 3 | B4: ='Revenue Forecast'!C5 -> 72578936 | C4: =B4*$J$3 -> 15967366 | D4: =1/(1+$J$1)^A4 -> 0.67497152 | E4: =C4*D4 -> 10777517 | F4: =1/(1+$J$2)^A4 -> 0.64065767 | G4: =C4*F4 -> 10229616 | I4: Terminal growth | J4: =Assumptions!B38 -> 0.03
A5: 4 | B5: ='Revenue Forecast'!C6 -> 84191566 | C5: =B5*$J$3 -> 18522145 | D5: =1/(1+$J$1)^A5 -> 0.59208028 | E5: =C5*D5 -> 10966596 | F5: =1/(1+$J$2)^A5 -> 0.5522911 | G5: =C5*F5 -> 10229616
A6: 5 | B6: ='Revenue Forecast'!C7 -> 95978385 | C6: =B6*$J$3 -> 21115245 | D6: =1/(1+$J$1)^A6 -> 0.51936866 | E6: =C6*D6 -> 10966596 | F6: =1/(1+$J$2)^A6 -> 0.47611302 | G6: =C6*F6 -> 10053243

Sheet Cap Table Pro Forma
A1: Post-round fully diluted ownership by individual holder
A2: Each legal holder from cap_table.csv is listed separately. Option Pool is a pool category (existing stock-plan Options rows + 15% refresh). Forsyth Equity combines Series A Preferred and Series B pro-rata primary. Share issuances use whole-share ROUND formulas from Assumptions.
A3: Holder | B3: Security / Position | C3: Pre-Round Shares | D3: New Shares | E3: Post-Round Shares | F3: Post-Round FD Ownership | G3: Source / Notes
A4: Jane Okonkwo | B4: Common | C4: 4200000 | D4: 0 | E4: =C4+D4 -> 4200000 | F4: =E4/$E$18 -> 0.17363715 | G4: cap_table.csv — co-founder CEO
A5: Marcus Chen | B5: Common | C5: 3800000 | D5: 0 | E5: =C5+D5 -> 3800000 | F5: =E5/$E$18 -> 0.15710028 | G5: cap_table.csv — co-founder CTO
A6: Employee exercises (YTD) | B6: Common | C6: 118400 | D6: 0 | E6: =C6+D6 -> 118400 | F6: =E6/$E$18 -> 0.00489491 | G6: cap_table.csv — routine option exercises
A7: Treasury shares | B7: Common | C7: 24000 | D7: 0 | E7: =C7+D7 -> 24000 | F7: =E7/$E$18 -> 0.00099221 | G7: cap_table.csv — repurchase reserve
A8: Employee stock purchase | B8: Common | C8: 48200 | D8: 0 | E8: =C8+D8 -> 48200 | F8: =E8/$E$18 -> 0.00199269 | G8: cap_table.csv — ESPP Q3 2024
A9: Dr. Elena Ruiz | B9: Advisor Warrant (unexercised FD) | C9: 43000 | D9: 0 | E9: =C9+D9 -> 43000 | F9: =E9/$E$18 -> 0.00177771 | G9: cap_table.csv — 43,000 unexercised in FD (42,000 exercised already in Employee exercises YTD)
A10: Strategic partner warrant | B10: Warrant | C10: 150000 | D10: 0 | E10: =C10+D10 -> 150000 | F10: =E10/$E$18 -> 0.00620133 | G10: cap_table.csv — LabCorp partnership
A11: Option Pool | B11: Existing allocated Options (stock plan) | C11: =Assumptions!B23 -> 1942000 | D11: 0 | E11: =C11+D11 -> 1942000 | F11: =E11/$E$18 -> 0.08028651 | G11: cap_table.csv Options rows (excludes available/empty pool stub; excludes Dr. Elena Ruiz advisor warrant from pool inventory)
A12: Forsyth Equity | B12: Series A Preferred + Series B Pro-Rata | C12: =Assumptions!B15 -> 6500000 | D12: =Assumptions!B21 -> 1625000 | E12: =C12+D12 -> 8125000 | F12: =E12/$E$18 -> 0.3359052 | G12: cap_table.csv Series A Preferred at $1.82; investor_brief.txt full pro-rata of $28M primary
A13: Vesper Growth | B13: SAFE conversion (base case; MFN outstanding) | C13: 0 | D13: =Assumptions!B19 -> 934756 | E13: =C13+D13 -> 934756 | F13: =E13/$E$18 -> 0.03864485 | G13: Whole-share ROUND of invested / applicable conversion price; MFN unresolved per sources
A14: Quorum Ventures | B14: SAFE conversion | C14: 0 | D14: =Assumptions!B20 -> 535360 | E14: =C14+D14 -> 535360 | F14: =E14/$E$18 -> 0.02213295 | G14: cap_table.csv — $55M cap, no discount; whole-share ROUND
A15: Octavian Capital | B15: Series B Primary (lead) | C15: 0 | D15: =Assumptions!B22 -> 2581400 | E15: =C15+D15 -> 2581400 | F15: =E15/$E$18 -> 0.1067207 | G15: Remainder of $28M primary after Forsyth pro-rata
A16: Option Pool | B16: 15% post-money refresh (board case) | C16: 0 | D16: =Assumptions!B24 -> 1686256 | E16: =C16+D16 -> 1686256 | F16: =E16/$E$18 -> 0.0697135 | G16: investor_brief.txt 15% target; ROUND whole shares; 12% alternate on Option pool cases
A18: Post-money FD total | E18: =SUM(E4:E16) -> 24188372 | F18: =SUM(F4:F16) -> 1 | G18: Must reconcile to Assumptions!B40 / Option pool cases E3
A20: Forsyth Equity — post-round total (callout)
A21: Forsyth Equity post-round shares | B21: =E12 -> 8125000 | C21: Series A + Series B pro-rata (formula-linked)
A22: Forsyth Equity post-round FD ownership | B22: =F12 -> 0.3359052 | C22: Post-round shares ÷ FD total

Sheet Valuation Summary
A1: Valuation summary — Helix Biotech Series B
A2: Method / metric | B2: Value | C2: Basis
A3: Revenue basis
A4: Normalized TTM ARR | B4: =Assumptions!B8 -> 38106380 | C4: Cohort build after pending-renewal exclusion
A5: NTM / Y1 ARR (forecast) | B5: =Assumptions!B9 -> 48776167 | C5: Revenue Forecast Y1 (Footnote 3 growth path)
A7: Revenue-multiple valuation
A8: Revenue multiple low (5.5x on Y1 NTM ARR) | B8: =Assumptions!B9*Assumptions!B31 -> 268268918 | C8: investor_brief.txt comps / Footnote 3
A9: Revenue multiple high (7.0x on Y1 NTM ARR) | B9: =Assumptions!B9*Assumptions!B32 -> 3.4143317e+08 | C9: investor_brief.txt comps / Footnote 3
A10: Midpoint revenue-multiple valuation | B10: =(B8+B9)/2 -> 3.0485104e+08 | C10: Average of 5.5x–7.0x NTM
A11: Downside EV (5.0x normalized TTM ARR) | B11: =Assumptions!B8*Assumptions!B33 -> 190531902 | C11: investor_brief.txt downside
A12: Peer-median NTM case (6.1x) — sensitivity base | B12: ='Revenue Forecast'!C3*Assumptions!B34 -> 2.9753462e+08 | C12: Ties to Sensitivity center cell ($297,534,618.15 base)
A14: DCF valuation
A15: DCF implied EV high (14% WACC) | B15: ='DCF Build'!E2+'DCF Build'!E3+'DCF Build'!E4+'DCF Build'!E5+'DCF Build'!E6+('DCF Build'!C6*(1+Assumptions!B38)/(Assumptions!B36-Assumptions!B38)/((1+Assumptions!B36)^5)) -> 1.5504952e+08 | C15: Five-year FCF + terminal
A16: DCF implied EV low (16% WACC) | B16: ='DCF Build'!G2+'DCF Build'!G3+'DCF Build'!G4+'DCF Build'!G5+'DCF Build'!G6+('DCF Build'!C6*(1+Assumptions!B38)/(Assumptions!B37-Assumptions!B38)/((1+Assumptions!B37)^5)) -> 1.2930437e+08 | C16: Five-year FCF + terminal
A17: Midpoint DCF-implied valuation | B17: =(B15+B16)/2 -> 1.4217694e+08 | C17: Average of 14%–16% WACC
A19: Selected / term-sheet cross-check
A20: Term sheet pre-money | B20: =Assumptions!B3 -> 112000000 | C20: investor_brief.txt — transaction terms
A21: Implied post-money before pool | B21: =Assumptions!B5 -> 140000000 | C21: investor_brief.txt
A22: Multiple vs DCF midpoint variance | B22: =B10-B17 -> 1.626741e+08 | C22: Reconciliation of midpoint methods

Sheet Sensitivity
A1: Sensitivity — retention stress × Y1 total ARR growth → forecast ARR → peer EV
A2: Footnote 3 Y1 growth is TOTAL ARR growth. Retention stress is a multiplicative stress vs the base path (scalar = NRR_case / 1.08; base scalar = 1.00). Absolute trailing NRR is NOT multiplied on top of total growth. Each case uses the same Y1 identity as Revenue Forecast: Normalized TTM × retention_stress × (1+growth). Center case ties to live Revenue Forecast!C3 and Valuation Summary peer-median EV.
A3: Live forecast drivers (linked)
A4: normalized_ttm_arr | B4: =Assumptions!B8 -> 38106380 | C4: retention_stress_scalar_base | D4: =Assumptions!B46 -> 1 | E4: y1_total_arr_growth | F4: =Assumptions!B39 -> 0.28
A5: trailing_nrr_diagnostic | B5: =Assumptions!B35 -> 1.08 | C5: peer_median_multiple | D5: =Assumptions!B34 -> 6.1 | E5: live_y1_arr_(Revenue Forecast) | F5: ='Revenue Forecast'!C3 -> 48776167
A6: live_peer_median_EV | B6: =F5*D5 -> 2.9753462e+08 | C6: valuation_summary_peer_check | D6: ='Valuation Summary'!B12 -> 2.9753462e+08
A8: Y1 ARR cases (feeds valuation) | B8: retention_stress = NRR_case / trailing_nrr_diagnostic | C8: base growth
A9: NRR case \ Growth → | B9: 0.22 | C9: 0.28 | D9: 0.34 | E9: stress
A10: 1.05 | B10: =$B$4*(A10/$B$5)*(1+B$9) -> 45198401 | C10: =$B$4*(A10/$B$5)*(1+C$9) -> 47421273 | D10: =$B$4*(A10/$B$5)*(1+D$9) -> 49644146 | E10: 0.972222
A11: 1.08 | B11: =$B$4*(A11/$B$5)*(1+B$9) -> 46489784 | C11: =$B$4*(A11/$B$5)*(1+C$9) -> 48776167 | D11: =$B$4*(A11/$B$5)*(1+D$9) -> 51062550 | E11: 1 | F11: base row (stress=1.00)
A12: 1.11 | B12: =$B$4*(A12/$B$5)*(1+B$9) -> 47781167 | C12: =$B$4*(A12/$B$5)*(1+C$9) -> 50131060 | D12: =$B$4*(A12/$B$5)*(1+D$9) -> 52480954 | E12: 1.027778
A14: Peer-median EV cases (= Y1 ARR × peer multiple)
A15: NRR case \ Growth → | B15: 0.22 | C15: 0.28 | D15: 0.34
A16: 1.05 | B16: =B10*$D$5 -> 2.7571025e+08 | C16: =C10*$D$5 -> 2.8926977e+08 | D16: =D10*$D$5 -> 3.0282929e+08
A17: 1.08 | B17: =B11*$D$5 -> 2.8358768e+08 | C17: =C11*$D$5 -> 2.9753462e+08 | D17: =D11*$D$5 -> 3.1148155e+08
A18: 1.11 | B18: =B12*$D$5 -> 2.9146512e+08 | C18: =C12*$D$5 -> 3.0579947e+08 | D18: =D12*$D$5 -> 3.2013382e+08
A20: Base-case tie-out
A21: Base Y1 ARR (matrix) | B21: =C11 -> 48776167 | C21: Live Revenue Forecast Y1 | D21: =F5 -> 48776167
A22: Base peer EV (matrix) | B22: =C17 -> 2.9753462e+08 | C22: Live peer EV / Valuation Summary | D22: =B6 -> 2.9753462e+08
A24: Methodology note | B24: Growth and retention are separate drivers. Base forecast uses retention_stress=1.00 and Footnote 3 total ARR growth (28%). Sensitivity NRR rows convert to stress via NRR/1.08 so the center does not re-apply absolute 108% NRR on top of total growth. Center peer EV equals normalized TTM × 1.28 × 6.1x = $297,534,618.15.

Sheet Option pool cases
A1: scenario | B1: target_post_money_pool_pct | C1: existing_pool_shares | D1: refresh_shares | E1: fd_post | F1: combined_pool_pct | G1: treatment
A2: Counsel side letter (12%) | B2: =Assumptions!B27 -> 0.12 | C2: =Assumptions!B23 -> 1942000 | D2: =ROUND(MAX((B2*Assumptions!B13-C2)/(1-B2),0),0) -> 861652 | E2: =Assumptions!B13+D2 -> 23363768 | F2: =(C2+D2)/E2 -> 0.11999999 | G2: 12% side letter from cap_table.csv; alternate only; whole-share ROUND
A3: Term sheet (15%) | B3: =Assumptions!B26 -> 0.15 | C3: =Assumptions!B23 -> 1942000 | D3: =ROUND(MAX((B3*Assumptions!B13-C3)/(1-B3),0),0) -> 1686256 | E3: =Assumptions!B13+D3 -> 24188372 | F3: =(C3+D3)/E3 -> 0.15000001 | G3: Board-approved; used on Cap Table Pro Forma; whole-share ROUND

Sheet Notes
A1: Source conflicts, methodology, and outstanding diligence
A2: section / topic | B2: detail
A3: CONFIRMED — Series A Preferred holder | B3: cap_table.csv lists Forsyth Equity as the Series A Preferred holder: 6,500,000 shares at $1.82/share (2022-04 close). No other holder is shown for that security.
A4: CONFIRMED — Forsyth Equity pro-rata | B4: investor_brief.txt allocates $10,816,850.51 of the $28,000,000 primary to Forsyth Equity (38.6316% of FD pre), matching the Series B Pro-Rata stub on cap_table.csv. That full pro-rata slice is used on the Cap Table Pro Forma.
A5: CONFIRMED — ARR bridge from retained cohort rows | B5: Cohort Build inventories all eight unique 2024 calendar-quarter Cohort Detail records from cohort_summary.xlsx, visibly excludes the duplicate FY2023-Q2 expansion line, and derives quarterly totals with SUMIFS on retained ending_arr. Those totals reconcile to Quarterly Rollup TTM $40,359,060.40. Footnote 1 excludes the Apex Diagnostics pending renewal ($2,252,680), producing normalized model ARR of $38,106,380.40 that feeds Revenue Forecast.
A6: CONFIRMED — Headline run-rate not binding | B6: investor_brief.txt also quotes a $42,100,000 headline run-rate that includes the pending Apex Diagnostics renewal. That headline is disclosed for context only and is not the binding valuation basis.
A7: CONFIRMED — Ending-ARR / retention definition | B7: Per cohort_summary.xlsx Definitions, gross_retention_pct is starting ARR retained before expansion and churn. Cohort Build ending_arr = starting_arr × gross_retention_pct/100 + expansion_arr − churn_arr. Churn is applied once via the −churn_arr term; gross_retention_pct is not a net-of-churn rate, so retention and churn are not double-counted.
A8: CONFIRMED — Duplicate FY2023-Q2 expansion | B8: The duplicate FY2023-Q2 expansion line remains in the Cohort Build inventory with include_flag=0 and an explicit exclusion reason. It is excluded from SUMIFS quarterly totals and normalized ARR (excluded once).
A9: CONFIRMED — Fiscal vs calendar quarters | B9: Per cohort_summary.xlsx fiscal-to-calendar mapping and investor_brief.txt Footnote 2, Cohort Build preserves calendar_quarter from the source map (e.g. FY2023-Q4 → 2024-Q1; FY2024-Q1 → 2024-Q3).
A10: MODELING ASSUMPTION — Forward growth path | B10: Revenue Forecast Y1 uses Footnote 3 total ARR growth (28%) with retention stress scalar = 1.00 on Assumptions. Absolute trailing cohort NRR (~1.08) is a diagnostic only and is not stacked onto total growth in the base case. Sensitivity converts NRR cases to stress = NRR/1.08 so growth and retention remain separate drivers; center peer-median EV = $297,534,618.15.
A11: MODELING ASSUMPTION — Vesper base-case conversion price | B11: Vesper Growth SAFE is modeled at the lower valuation-cap price (≈$2.6745/share) versus the ≈20%-discounted Series B price because that is the contractual lower-of mechanics. This is a modeling assumption for the pro forma while MFN diligence remains open — not a finding that MFN was cleared or that no better terms exist.
A12: UNRESOLVED DILIGENCE — Vesper Growth MFN | B12: The MFN remains outstanding/unresolved per cap_table.csv (status field: 'MFN clause outstanding') and investor_brief.txt (open diligence: document MFN treatment relative to Series B price). No source clears the MFN, confirms review completion, discloses a better MFN term, or waives the clause. Conversion shares remain conditional until MFN diligence closes. No alternate MFN price is modeled because the inputs do not quantify one.
A13: CONDITIONAL — Option pool 12% vs 15% | B13: investor_brief.txt / term sheet: 15% post-money refresh used on Cap Table Pro Forma (1,686,256 refresh; 24,188,372 FD post). cap_table.csv counsel side-letter: 12% alternate on Option pool cases (861,652 refresh). Existing stock-plan pool base = 1,942,000 (Options rows only; Dr. Elena Ruiz advisor warrant excluded from pool inventory but retained in FD).
... A17: Board recommendation / open items | B17: Proceed with the Octavian Capital term sheet at $112M pre-money, $28,000,000 primary, and 15% post-money pool per investor_brief.txt. Ownership and conversion figures that depend on Vesper Growth remain conditional while the MFN diligence item is open; close that item before treating conversion shares as final.
