Workbook

Sheet Assumptions
A1: Crowhaven Logistics — YE 2025-12-31 factors
A2: actuarial_factor_memo.txt | fully insured primary
A5: Item | B5: Value | C5: Source
A6: Paid LDF 12 | B6: 1.82 | C6: actuarial_factor_memo.txt
A7: Paid LDF 24 | B7: 1.41 | C7: actuarial_factor_memo.txt
A8: Paid LDF 36 | B8: 1.18 | C8: actuarial_factor_memo.txt
A9: Paid LDF 48 | B9: 1.06 | C9: actuarial_factor_memo.txt
A10: Large Loss Claim | B10: CLM-AUTO-2023-4412 | C10: Large Loss Adjustment
A11: Large Loss Paid | B11: 185220.4 | C11: Carve from AY 2023 paid
A12: Closed Claim Drop | B12: CLM-AUTO-2024-0908 | C12: Final payment 2025-12-12
A13: VOID Claim Drop | B13: CLM-AUTO-2024-0000 | C13: VOID status
A14: Earned Premium | B14: 2850220.4 | C14: actuarial_factor_memo.txt
A15: Refer Threshold | B15: 0.685 | C15: actuarial_factor_memo.txt
A16: Decline Threshold | B16: 0.85 | C16: actuarial_factor_memo.txt
A17: Prior Booked Reserve | B17: 1104220.2 | C17: 2024-12-31 context
A18: Evaluation Date | B18: 46022 | C18: Year-end
A19: Renewal Date | B19: 46082 | C19: Package renewal
A20: Policy | B20: PKG-CA-GL-IN-2025-4418 | C20: Subject policy
A21: Draft LDF 12 (unused) | B21: 1.65 | C21: Definitions superseded
A22: Draft LDF 24 (unused) | B22: 1.28 | C22: Definitions superseded
A23: Draft LDF 36 (unused) | B23: 1.12 | C23: Definitions superseded
A24: Draft LDF 48 (unused) | B24: 1.03 | C24: Definitions superseded
A25: Duplicate Review | B25: CLM-GL-2025-0144 | C25: Keep latest as_of
A27: Governing source
A28: Paid LDFs 1.82/1.41/1.18/1.06 — actuarial_factor_memo.txt; Definitions draft 1.65/1.28/1.12/1.03 superseded.

Sheet Case Inventory
A1: Crowhaven Logistics — open claims @ 2025-12-31
A2: Source: crowhaven-logistics_open_claims.csv
A4: Claim Number | B4: AY | C4: Line | D4: Claimant | E4: Status | F4: Paid to Date | G4: Case Reserve | H4: As Of | I4: LL Flag | J4: TPA Note | K4: Include | L4: Cleaned Case | M4: Is LL | N4: Attritional Case | O4: LL Case | P4: Disposition
A5: CLM-AUTO-2022-0188 | B5: 2022 | C5: Commercial Auto | D5: R. Holcomb | E5: Open | F5: 14220.18 | G5: 4810.55 | H5: 46019 | I5: N | K5: =IF(OR(UPPER(E5)="VOID",A5=Assumptions!$B$13),FALSE,IF(A5=Assumptions!$B$12,FALSE,IF(H5<>MAXIFS($H$5:$H$45,$A$5:$A$45,A5),FALSE,TRUE))) -> 1 | L5: =IF(K5,G5,0) -> 4810.55 | M5: =IF(A5=Assumptions!$B$10,TRUE,FALSE) -> 0 | N5: =IF(AND(K5,NOT(M5)),G5,0) -> 4810.55 | O5: =IF(AND(K5,M5),G5,0) -> 0 | P5: =IF(OR(UPPER(E5)="VOID",A5=Assumptions!$B$13),"Drop-VOID",IF(A5=Assumptions!$B$12,"Drop-closed",IF(H5<>MAXIFS($H$5:$H$45,$A$5:$A$45,A5),"Drop-dup",IF(M5,"Keep-LL","Keep"))))
A6: CLM-AUTO-2022-0441 | B6: 2022 | C6: Commercial Auto | D6: S. Mercado | E6: Open | F6: 9880.4 | G6: 2110 | H6: 46019 | I6: N | K6: =IF(OR(UPPER(E6)="VOID",A6=Assumptions!$B$13),FALSE,IF(A6=Assumptions!$B$12,FALSE,IF(H6<>MAXIFS($H$5:$H$45,$A$5:$A$45,A6),FALSE,TRUE))) -> 1 | L6: =IF(K6,G6,0) -> 2110 | M6: =IF(A6=Assumptions!$B$10,TRUE,FALSE) -> 0 | N6: =IF(AND(K6,NOT(M6)),G6,0) -> 2110 | O6: =IF(AND(K6,M6),G6,0) -> 0 | P6: =IF(OR(UPPER(E6)="VOID",A6=Assumptions!$B$13),"Drop-VOID",IF(A6=Assumptions!$B$12,"Drop-closed",IF(H6<>MAXIFS($H$5:$H$45,$A$5:$A$45,A6),"Drop-dup",IF(M6,"Keep-LL","Keep"))))
A7: CLM-AUTO-2022-0612 | B7: 2022 | C7: Commercial Auto | D7: P. Nguyen | E7: Open | F7: 22640.55 | G7: 5200.18 | H7: 46019 | I7: N | K7: =IF(OR(UPPER(E7)="VOID",A7=Assumptions!$B$13),FALSE,IF(A7=Assumptions!$B$12,FALSE,IF(H7<>MAXIFS($H$5:$H$45,$A$5:$A$45,A7),FALSE,TRUE))) -> 1 | L7: =IF(K7,G7,0) -> 5200.18 | M7: =IF(A7=Assumptions!$B$10,TRUE,FALSE) -> 0 | N7: =IF(AND(K7,NOT(M7)),G7,0) -> 5200.18 | O7: =IF(AND(K7,M7),G7,0) -> 0 | P7: =IF(OR(UPPER(E7)="VOID",A7=Assumptions!$B$13),"Drop-VOID",IF(A7=Assumptions!$B$12,"Drop-closed",IF(H7<>MAXIFS($H$5:$H$45,$A$5:$A$45,A7),"Drop-dup",IF(M7,"Keep-LL","Keep"))))
A8: CLM-AUTO-2022-0790 | B8: 2022 | C8: Commercial Auto | D8: L. Ortiz | E8: Open | F8: 6110.22 | G8: 1840.55 | H8: 46019 | I8: N | K8: =IF(OR(UPPER(E8)="VOID",A8=Assumptions!$B$13),FALSE,IF(A8=Assumptions!$B$12,FALSE,IF(H8<>MAXIFS($H$5:$H$45,$A$5:$A$45,A8),FALSE,TRUE))) -> 1 | L8: =IF(K8,G8,0) -> 1840.55 | M8: =IF(A8=Assumptions!$B$10,TRUE,FALSE) -> 0 | N8: =IF(AND(K8,NOT(M8)),G8,0) -> 1840.55 | O8: =IF(AND(K8,M8),G8,0) -> 0 | P8: =IF(OR(UPPER(E8)="VOID",A8=Assumptions!$B$13),"Drop-VOID",IF(A8=Assumptions!$B$12,"Drop-closed",IF(H8<>MAXIFS($H$5:$H$45,$A$5:$A$45,A8),"Drop-dup",IF(M8,"Keep-LL","Keep"))))
A9: CLM-AUTO-2022-1033 | B9: 2022 | C9: Commercial Auto | D9: W. Carmichael | E9: Open | F9: 3110.18 | G9: 2220.4 | H9: 46019 | I9: N | K9: =IF(OR(UPPER(E9)="VOID",A9=Assumptions!$B$13),FALSE,IF(A9=Assumptions!$B$12,FALSE,IF(H9<>MAXIFS($H$5:$H$45,$A$5:$A$45,A9),FALSE,TRUE))) -> 1 | L9: =IF(K9,G9,0) -> 2220.4 | M9: =IF(A9=Assumptions!$B$10,TRUE,FALSE) -> 0 | N9: =IF(AND(K9,NOT(M9)),G9,0) -> 2220.4 | O9: =IF(AND(K9,M9),G9,0) -> 0 | P9: =IF(OR(UPPER(E9)="VOID",A9=Assumptions!$B$13),"Drop-VOID",IF(A9=Assumptions!$B$12,"Drop-closed",IF(H9<>MAXIFS($H$5:$H$45,$A$5:$A$45,A9),"Drop-dup",IF(M9,"Keep-LL","Keep"))))
A10: CLM-AUTO-2022-1564 | B10: 2022 | C10: Commercial Auto | D10: Q. Bartlett | E10: Open | F10: 6631.78 | G10: 4781.12 | H10: 46019 | I10: N | K10: =IF(OR(UPPER(E10)="VOID",A10=Assumptions!$B$13),FALSE,IF(A10=Assumptions!$B$12,FALSE,IF(H10<>MAXIFS($H$5:$H$45,$A$5:$A$45,A10),FALSE,TRUE))) -> 1 | L10: =IF(K10,G10,0) -> 4781.12 | M10: =IF(A10=Assumptions!$B$10,TRUE,FALSE) -> 0 | N10: =IF(AND(K10,NOT(M10)),G10,0) -> 4781.12 | O10: =IF(AND(K10,M10),G10,0) -> 0 | P10: =IF(OR(UPPER(E10)="VOID",A10=Assumptions!$B$13),"Drop-VOID",IF(A10=Assumptions!$B$12,"Drop-closed",IF(H10<>MAXIFS($H$5:$H$45,$A$5:$A$45,A10),"Drop-dup",IF(M10,"Keep-LL","Keep"))))
A11: CLM-GL-2022-0033 | B11: 2022 | C11: General Liability | D11: Warehouse slip | E11: Open | F11: 7220.18 | G11: 2840.55 | H11: 46019 | I11: N | K11: =IF(OR(UPPER(E11)="VOID",A11=Assumptions!$B$13),FALSE,IF(A11=Assumptions!$B$12,FALSE,IF(H11<>MAXIFS($H$5:$H$45,$A$5:$A$45,A11),FALSE,TRUE))) -> 1 | L11: =IF(K11,G11,0) -> 2840.55 | M11: =IF(A11=Assumptions!$B$10,TRUE,FALSE) -> 0 | N11: =IF(AND(K11,NOT(M11)),G11,0) -> 2840.55 | O11: =IF(AND(K11,M11),G11,0) -> 0 | P11: =IF(OR(UPPER(E11)="VOID",A11=Assumptions!$B$13),"Drop-VOID",IF(A11=Assumptions!$B$12,"Drop-closed",IF(H11<>MAXIFS($H$5:$H$45,$A$5:$A$45,A11),"Drop-dup",IF(M11,"Keep-LL","Keep"))))
A12: CLM-AUTO-2023-0091 | B12: 2023 | C12: Commercial Auto | D12: K. Brennan | E12: Open | F12: 18420.4 | G12: 6110.18 | H12: 46019 | I12: N | K12: =IF(OR(UPPER(E12)="VOID",A12=Assumptions!$B$13),FALSE,IF(A12=Assumptions!$B$12,FALSE,IF(H12<>MAXIFS($H$5:$H$45,$A$5:$A$45,A12),FALSE,TRUE))) -> 1 | L12: =IF(K12,G12,0) -> 6110.18 | M12: =IF(A12=Assumptions!$B$10,TRUE,FALSE) -> 0 | N12: =IF(AND(K12,NOT(M12)),G12,0) -> 6110.18 | O12: =IF(AND(K12,M12),G12,0) -> 0 | P12: =IF(OR(UPPER(E12)="VOID",A12=Assumptions!$B$13),"Drop-VOID",IF(A12=Assumptions!$B$12,"Drop-closed",IF(H12<>MAXIFS($H$5:$H$45,$A$5:$A$45,A12),"Drop-dup",IF(M12,"Keep-LL","Keep"))))
A13: CLM-AUTO-2023-0275 | B13: 2023 | C13: Commercial Auto | D13: D. Singh | E13: Open | F13: 31220.18 | G13: 8880.4 | H13: 46019 | I13: N | K13: =IF(OR(UPPER(E13)="VOID",A13=Assumptions!$B$13),FALSE,IF(A13=Assumptions!$B$12,FALSE,IF(H13<>MAXIFS($H$5:$H$45,$A$5:$A$45,A13),FALSE,TRUE))) -> 1 | L13: =IF(K13,G13,0) -> 8880.4 | M13: =IF(A13=Assumptions!$B$10,TRUE,FALSE) -> 0 | N13: =IF(AND(K13,NOT(M13)),G13,0) -> 8880.4 | O13: =IF(AND(K13,M13),G13,0) -> 0 | P13: =IF(OR(UPPER(E13)="VOID",A13=Assumptions!$B$13),"Drop-VOID",IF(A13=Assumptions!$B$12,"Drop-closed",IF(H13<>MAXIFS($H$5:$H$45,$A$5:$A$45,A13),"Drop-dup",IF(M13,"Keep-LL","Keep"))))
A14: CLM-AUTO-2023-0510 | B14: 2023 | C14: Commercial Auto | D14: M. Alvarez | E14: Open | F14: 12640.55 | G14: 4220.18 | H14: 46019 | I14: N | K14: =IF(OR(UPPER(E14)="VOID",A14=Assumptions!$B$13),FALSE,IF(A14=Assumptions!$B$12,FALSE,IF(H14<>MAXIFS($H$5:$H$45,$A$5:$A$45,A14),FALSE,TRUE))) -> 1 | L14: =IF(K14,G14,0) -> 4220.18 | M14: =IF(A14=Assumptions!$B$10,TRUE,FALSE) -> 0 | N14: =IF(AND(K14,NOT(M14)),G14,0) -> 4220.18 | O14: =IF(AND(K14,M14),G14,0) -> 0 | P14: =IF(OR(UPPER(E14)="VOID",A14=Assumptions!$B$13),"Drop-VOID",IF(A14=Assumptions!$B$12,"Drop-closed",IF(H14<>MAXIFS($H$5:$H$45,$A$5:$A$45,A14),"Drop-dup",IF(M14,"Keep-LL","Keep"))))
A15: CLM-AUTO-2023-0666 | B15: 2023 | C15: Commercial Auto | D15: J. Whitaker | E15: Open | F15: 27110 | G15: 7640.55 | H15: 46019 | I15: N | K15: =IF(OR(UPPER(E15)="VOID",A15=Assumptions!$B$13),FALSE,IF(A15=Assumptions!$B$12,FALSE,IF(H15<>MAXIFS($H$5:$H$45,$A$5:$A$45,A15),FALSE,TRUE))) -> 1 | L15: =IF(K15,G15,0) -> 7640.55 | M15: =IF(A15=Assumptions!$B$10,TRUE,FALSE) -> 0 | N15: =IF(AND(K15,NOT(M15)),G15,0) -> 7640.55 | O15: =IF(AND(K15,M15),G15,0) -> 0 | P15: =IF(OR(UPPER(E15)="VOID",A15=Assumptions!$B$13),"Drop-VOID",IF(A15=Assumptions!$B$12,"Drop-closed",IF(H15<>MAXIFS($H$5:$H$45,$A$5:$A$45,A15),"Drop-dup",IF(M15,"Keep-LL","Keep"))))
A16: CLM-AUTO-2023-0822 | B16: 2023 | C16: Commercial Auto | D16: T. Brooks | E16: Open | F16: 8880.4 | G16: 3220.18 | H16: 46019 | I16: N | K16: =IF(OR(UPPER(E16)="VOID",A16=Assumptions!$B$13),FALSE,IF(A16=Assumptions!$B$12,FALSE,IF(H16<>MAXIFS($H$5:$H$45,$A$5:$A$45,A16),FALSE,TRUE))) -> 1 | L16: =IF(K16,G16,0) -> 3220.18 | M16: =IF(A16=Assumptions!$B$10,TRUE,FALSE) -> 0 | N16: =IF(AND(K16,NOT(M16)),G16,0) -> 3220.18 | O16: =IF(AND(K16,M16),G16,0) -> 0 | P16: =IF(OR(UPPER(E16)="VOID",A16=Assumptions!$B$13),"Drop-VOID",IF(A16=Assumptions!$B$12,"Drop-closed",IF(H16<>MAXIFS($H$5:$H$45,$A$5:$A$45,A16),"Drop-dup",IF(M16,"Keep-LL","Keep"))))
A17: CLM-AUTO-2023-4412 | B17: 2023 | C17: Commercial Auto | D17: Multi-vehicle I-65 | E17: Open | F17: 185220.4 | G17: 142880.4 | H17: 46019 | I17: Y | J17: Severity committee; see actuarial memo | K17: =IF(OR(UPPER(E17)="VOID",A17=Assumptions!$B$13),FALSE,IF(A17=Assumptions!$B$12,FALSE,IF(H17<>MAXIFS($H$5:$H$45,$A$5:$A$45,A17),FALSE,TRUE))) -> 1 | L17: =IF(K17,G17,0) -> 142880.4 | M17: =IF(A17=Assumptions!$B$10,TRUE,FALSE) -> 1 | N17: =IF(AND(K17,NOT(M17)),G17,0) -> 0 | O17: =IF(AND(K17,M17),G17,0) -> 142880.4 | P17: =IF(OR(UPPER(E17)="VOID",A17=Assumptions!$B$13),"Drop-VOID",IF(A17=Assumptions!$B$12,"Drop-closed",IF(H17<>MAXIFS($H$5:$H$45,$A$5:$A$45,A17),"Drop-dup",IF(M17,"Keep-LL","Keep"))))
A18: CLM-GL-2023-0118 | B18: 2023 | C18: General Liability | D18: Dock damage | E18: Open | F18: 15640.4 | G18: 5110.18 | H18: 46019 | I18: N | K18: =IF(OR(UPPER(E18)="VOID",A18=Assumptions!$B$13),FALSE,IF(A18=Assumptions!$B$12,FALSE,IF(H18<>MAXIFS($H$5:$H$45,$A$5:$A$45,A18),FALSE,TRUE))) -> 1 | L18: =IF(K18,G18,0) -> 5110.18 | M18: =IF(A18=Assumptions!$B$10,TRUE,FALSE) -> 0 | N18: =IF(AND(K18,NOT(M18)),G18,0) -> 5110.18 | O18: =IF(AND(K18,M18),G18,0) -> 0 | P18: =IF(OR(UPPER(E18)="VOID",A18=Assumptions!$B$13),"Drop-VOID",IF(A18=Assumptions!$B$12,"Drop-closed",IF(H18<>MAXIFS($H$5:$H$45,$A$5:$A$45,A18),"Drop-dup",IF(M18,"Keep-LL","Keep"))))
A19: CLM-GL-2023-0290 | B19: 2023 | C19: General Liability | D19: Customer injury | E19: Open | F19: 28880.55 | G19: 8220.4 | H19: 46019 | I19: N | K19: =IF(OR(UPPER(E19)="VOID",A19=Assumptions!$B$13),FALSE,IF(A19=Assumptions!$B$12,FALSE,IF(H19<>MAXIFS($H$5:$H$45,$A$5:$A$45,A19),FALSE,TRUE))) -> 1 | L19: =IF(K19,G19,0) -> 8220.4 | M19: =IF(A19=Assumptions!$B$10,TRUE,FALSE) -> 0 | N19: =IF(AND(K19,NOT(M19)),G19,0) -> 8220.4 | O19: =IF(AND(K19,M19),G19,0) -> 0 | P19: =IF(OR(UPPER(E19)="VOID",A19=Assumptions!$B$13),"Drop-VOID",IF(A19=Assumptions!$B$12,"Drop-closed",IF(H19<>MAXIFS($H$5:$H$45,$A$5:$A$45,A19),"Drop-dup",IF(M19,"Keep-LL","Keep"))))
A20: CLM-GL-2023-0442 | B20: 2023 | C20: General Liability | D20: Loading bay leak | E20: Open | F20: 3990.58 | G20: 2860.58 | H20: 46019 | I20: N | K20: =IF(OR(UPPER(E20)="VOID",A20=Assumptions!$B$13),FALSE,IF(A20=Assumptions!$B$12,FALSE,IF(H20<>MAXIFS($H$5:$H$45,$A$5:$A$45,A20),FALSE,TRUE))) -> 1 | L20: =IF(K20,G20,0) -> 2860.58 | M20: =IF(A20=Assumptions!$B$10,TRUE,FALSE) -> 0 | N20: =IF(AND(K20,NOT(M20)),G20,0) -> 2860.58 | O20: =IF(AND(K20,M20),G20,0) -> 0 | P20: =IF(OR(UPPER(E20)="VOID",A20=Assumptions!$B$13),"Drop-VOID",IF(A20=Assumptions!$B$12,"Drop-closed",IF(H20<>MAXIFS($H$5:$H$45,$A$5:$A$45,A20),"Drop-dup",IF(M20,"Keep-LL","Keep"))))
A21: CLM-GL-2023-0701 | B21: 2023 | C21: General Liability | D21: Gate hinge injury | E21: Open | F21: 7512.18 | G21: 5421.3 | H21: 46019 | I21: N | K21: =IF(OR(UPPER(E21)="VOID",A21=Assumptions!$B$13),FALSE,IF(A21=Assumptions!$B$12,FALSE,IF(H21<>MAXIFS($H$5:$H$45,$A$5:$A$45,A21),FALSE,TRUE))) -> 1 | L21: =IF(K21,G21,0) -> 5421.3 | M21: =IF(A21=Assumptions!$B$10,TRUE,FALSE) -> 0 | N21: =IF(AND(K21,NOT(M21)),G21,0) -> 5421.3 | O21: =IF(AND(K21,M21),G21,0) -> 0 | P21: =IF(OR(UPPER(E21)="VOID",A21=Assumptions!$B$13),"Drop-VOID",IF(A21=Assumptions!$B$12,"Drop-closed",IF(H21<>MAXIFS($H$5:$H$45,$A$5:$A$45,A21),"Drop-dup",IF(M21,"Keep-LL","Keep"))))
A22: CLM-AUTO-2024-0000 | B22: 2024 | C22: Commercial Auto | D22: Cancelled FNOL | E22: VOID | F22: 0 | G22: 99999 | H22: 45659 | I22: N | J22: Voided extract artifact — ignore | K22: =IF(OR(UPPER(E22)="VOID",A22=Assumptions!$B$13),FALSE,IF(A22=Assumptions!$B$12,FALSE,IF(H22<>MAXIFS($H$5:$H$45,$A$5:$A$45,A22),FALSE,TRUE))) -> 0 | L22: =IF(K22,G22,0) -> 0 | M22: =IF(A22=Assumptions!$B$10,TRUE,FALSE) -> 0 | N22: =IF(AND(K22,NOT(M22)),G22,0) -> 0 | O22: =IF(AND(K22,M22),G22,0) -> 0 | P22: =IF(OR(UPPER(E22)="VOID",A22=Assumptions!$B$13),"Drop-VOID",IF(A22=Assumptions!$B$12,"Drop-closed",IF(H22<>MAXIFS($H$5:$H$45,$A$5:$A$45,A22),"Drop-dup",IF(M22,"Keep-LL","Keep"))))
A23: CLM-AUTO-2024-0044 | B23: 2024 | C23: Commercial Auto | D23: A. Patel | E23: Open | F23: 24110.22 | G23: 12880.4 | H23: 46019 | I23: N | K23: =IF(OR(UPPER(E23)="VOID",A23=Assumptions!$B$13),FALSE,IF(A23=Assumptions!$B$12,FALSE,IF(H23<>MAXIFS($H$5:$H$45,$A$5:$A$45,A23),FALSE,TRUE))) -> 1 | L23: =IF(K23,G23,0) -> 12880.4 | M23: =IF(A23=Assumptions!$B$10,TRUE,FALSE) -> 0 | N23: =IF(AND(K23,NOT(M23)),G23,0) -> 12880.4 | O23: =IF(AND(K23,M23),G23,0) -> 0 | P23: =IF(OR(UPPER(E23)="VOID",A23=Assumptions!$B$13),"Drop-VOID",IF(A23=Assumptions!$B$12,"Drop-closed",IF(H23<>MAXIFS($H$5:$H$45,$A$5:$A$45,A23),"Drop-dup",IF(M23,"Keep-LL","Keep"))))
A24: CLM-AUTO-2024-0318 | B24: 2024 | C24: Commercial Auto | D24: C. Ramirez | E24: Open | F24: 16420.18 | G24: 9640.55 | H24: 46019 | I24: N | K24: =IF(OR(UPPER(E24)="VOID",A24=Assumptions!$B$13),FALSE,IF(A24=Assumptions!$B$12,FALSE,IF(H24<>MAXIFS($H$5:$H$45,$A$5:$A$45,A24),FALSE,TRUE))) -> 1 | L24: =IF(K24,G24,0) -> 9640.55 | M24: =IF(A24=Assumptions!$B$10,TRUE,FALSE) -> 0 | N24: =IF(AND(K24,NOT(M24)),G24,0) -> 9640.55 | O24: =IF(AND(K24,M24),G24,0) -> 0 | P24: =IF(OR(UPPER(E24)="VOID",A24=Assumptions!$B$13),"Drop-VOID",IF(A24=Assumptions!$B$12,"Drop-closed",IF(H24<>MAXIFS($H$5:$H$45,$A$5:$A$45,A24),"Drop-dup",IF(M24,"Keep-LL","Keep"))))
A25: CLM-AUTO-2024-0555 | B25: 2024 | C25: Commercial Auto | D25: E. Cho | E25: Open | F25: 33220.4 | G25: 18110.18 | H25: 46019 | I25: N | K25: =IF(OR(UPPER(E25)="VOID",A25=Assumptions!$B$13),FALSE,IF(A25=Assumptions!$B$12,FALSE,IF(H25<>MAXIFS($H$5:$H$45,$A$5:$A$45,A25),FALSE,TRUE))) -> 1 | L25: =IF(K25,G25,0) -> 18110.18 | M25: =IF(A25=Assumptions!$B$10,TRUE,FALSE) -> 0 | N25: =IF(AND(K25,NOT(M25)),G25,0) -> 18110.18 | O25: =IF(AND(K25,M25),G25,0) -> 0 | P25: =IF(OR(UPPER(E25)="VOID",A25=Assumptions!$B$13),"Drop-VOID",IF(A25=Assumptions!$B$12,"Drop-closed",IF(H25<>MAXIFS($H$5:$H$45,$A$5:$A$45,A25),"Drop-dup",IF(M25,"Keep-LL","Keep"))))
A26: CLM-AUTO-2024-0712 | B26: 2024 | C26: Commercial Auto | D26: N. Foster | E26: Open | F26: 11880.55 | G26: 7220.4 | H26: 46019 | I26: N | K26: =IF(OR(UPPER(E26)="VOID",A26=Assumptions!$B$13),FALSE,IF(A26=Assumptions!$B$12,FALSE,IF(H26<>MAXIFS($H$5:$H$45,$A$5:$A$45,A26),FALSE,TRUE))) -> 1 | L26: =IF(K26,G26,0) -> 7220.4 | M26: =IF(A26=Assumptions!$B$10,TRUE,FALSE) -> 0 | N26: =IF(AND(K26,NOT(M26)),G26,0) -> 7220.4 | O26: =IF(AND(K26,M26),G26,0) -> 0 | P26: =IF(OR(UPPER(E26)="VOID",A26=Assumptions!$B$13),"Drop-VOID",IF(A26=Assumptions!$B$12,"Drop-closed",IF(H26<>MAXIFS($H$5:$H$45,$A$5:$A$45,A26),"Drop-dup",IF(M26,"Keep-LL","Keep"))))
A27: CLM-AUTO-2024-0880 | B27: 2024 | C27: Commercial Auto | D27: B. Keller | E27: Open | F27: 19640.18 | G27: 11410 | H27: 46019 | I27: N | K27: =IF(OR(UPPER(E27)="VOID",A27=Assumptions!$B$13),FALSE,IF(A27=Assumptions!$B$12,FALSE,IF(H27<>MAXIFS($H$5:$H$45,$A$5:$A$45,A27),FALSE,TRUE))) -> 1 | L27: =IF(K27,G27,0) -> 11410 | M27: =IF(A27=Assumptions!$B$10,TRUE,FALSE) -> 0 | N27: =IF(AND(K27,NOT(M27)),G27,0) -> 11410 | O27: =IF(AND(K27,M27),G27,0) -> 0 | P27: =IF(OR(UPPER(E27)="VOID",A27=Assumptions!$B$13),"Drop-VOID",IF(A27=Assumptions!$B$12,"Drop-closed",IF(H27<>MAXIFS($H$5:$H$45,$A$5:$A$45,A27),"Drop-dup",IF(M27,"Keep-LL","Keep"))))
A28: CLM-AUTO-2024-0908 | B28: 2024 | C28: Commercial Auto | D28: C. Delgado | E28: Open | F28: 41880.4 | G28: 18220 | H28: 45996 | I28: N | J28: Final indemnity issued 2025-12-12; file closed — inventory lag | K28: =IF(OR(UPPER(E28)="VOID",A28=Assumptions!$B$13),FALSE,IF(A28=Assumptions!$B$12,FALSE,IF(H28<>MAXIFS($H$5:$H$45,$A$5:$A$45,A28),FALSE,TRUE))) -> 0 | L28: =IF(K28,G28,0) -> 0 | M28: =IF(A28=Assumptions!$B$10,TRUE,FALSE) -> 0 | N28: =IF(AND(K28,NOT(M28)),G28,0) -> 0 | O28: =IF(AND(K28,M28),G28,0) -> 0 | P28: =IF(OR(UPPER(E28)="VOID",A28=Assumptions!$B$13),"Drop-VOID",IF(A28=Assumptions!$B$12,"Drop-closed",IF(H28<>MAXIFS($H$5:$H$45,$A$5:$A$45,A28),"Drop-dup",IF(M28,"Keep-LL","Keep"))))
A29: CLM-AUTO-2024-1190 | B29: 2024 | C29: Commercial Auto | D29: V. Serrano | E29: Open | F29: 4870.98 | G29: 3500.76 | H29: 46019 | I29: N | K29: =IF(OR(UPPER(E29)="VOID",A29=Assumptions!$B$13),FALSE,IF(A29=Assumptions!$B$12,FALSE,IF(H29<>MAXIFS($H$5:$H$45,$A$5:$A$45,A29),FALSE,TRUE))) -> 1 | L29: =IF(K29,G29,0) -> 3500.76 | M29: =IF(A29=Assumptions!$B$10,TRUE,FALSE) -> 0 | N29: =IF(AND(K29,NOT(M29)),G29,0) -> 3500.76 | O29: =IF(AND(K29,M29),G29,0) -> 0 | P29: =IF(OR(UPPER(E29)="VOID",A29=Assumptions!$B$13),"Drop-VOID",IF(A29=Assumptions!$B$12,"Drop-closed",IF(H29<>MAXIFS($H$5:$H$45,$A$5:$A$45,A29),"Drop-dup",IF(M29,"Keep-LL","Keep"))))
A30: CLM-AUTO-2024-1628 | B30: 2024 | C30: Commercial Auto | D30: Z. Ingram | E30: Open | F30: 8392.58 | G30: 6061.48 | H30: 46019 | I30: N | K30: =IF(OR(UPPER(E30)="VOID",A30=Assumptions!$B$13),FALSE,IF(A30=Assumptions!$B$12,FALSE,IF(H30<>MAXIFS($H$5:$H$45,$A$5:$A$45,A30),FALSE,TRUE))) -> 1 | L30: =IF(K30,G30,0) -> 6061.48 | M30: =IF(A30=Assumptions!$B$10,TRUE,FALSE) -> 0 | N30: =IF(AND(K30,NOT(M30)),G30,0) -> 6061.48 | O30: =IF(AND(K30,M30),G30,0) -> 0 | P30: =IF(OR(UPPER(E30)="VOID",A30=Assumptions!$B$13),"Drop-VOID",IF(A30=Assumptions!$B$12,"Drop-closed",IF(H30<>MAXIFS($H$5:$H$45,$A$5:$A$45,A30),"Drop-dup",IF(M30,"Keep-LL","Keep"))))
A31: CLM-GL-2024-0077 | B31: 2024 | C31: General Liability | D31: Forklift strike | E31: Open | F31: 12110.18 | G31: 8640.55 | H31: 46019 | I31: N | K31: =IF(OR(UPPER(E31)="VOID",A31=Assumptions!$B$13),FALSE,IF(A31=Assumptions!$B$12,FALSE,IF(H31<>MAXIFS($H$5:$H$45,$A$5:$A$45,A31),FALSE,TRUE))) -> 1 | L31: =IF(K31,G31,0) -> 8640.55 | M31: =IF(A31=Assumptions!$B$10,TRUE,FALSE) -> 0 | N31: =IF(AND(K31,NOT(M31)),G31,0) -> 8640.55 | O31: =IF(AND(K31,M31),G31,0) -> 0 | P31: =IF(OR(UPPER(E31)="VOID",A31=Assumptions!$B$13),"Drop-VOID",IF(A31=Assumptions!$B$12,"Drop-closed",IF(H31<>MAXIFS($H$5:$H$45,$A$5:$A$45,A31),"Drop-dup",IF(M31,"Keep-LL","Keep"))))
A32: CLM-GL-2024-0215 | B32: 2024 | C32: General Liability | D32: Cargo spill | E32: Open | F32: 18420.4 | G32: 10880.18 | H32: 46019 | I32: N | K32: =IF(OR(UPPER(E32)="VOID",A32=Assumptions!$B$13),FALSE,IF(A32=Assumptions!$B$12,FALSE,IF(H32<>MAXIFS($H$5:$H$45,$A$5:$A$45,A32),FALSE,TRUE))) -> 1 | L32: =IF(K32,G32,0) -> 10880.18 | M32: =IF(A32=Assumptions!$B$10,TRUE,FALSE) -> 0 | N32: =IF(AND(K32,NOT(M32)),G32,0) -> 10880.18 | O32: =IF(AND(K32,M32),G32,0) -> 0 | P32: =IF(OR(UPPER(E32)="VOID",A32=Assumptions!$B$13),"Drop-VOID",IF(A32=Assumptions!$B$12,"Drop-closed",IF(H32<>MAXIFS($H$5:$H$45,$A$5:$A$45,A32),"Drop-dup",IF(M32,"Keep-LL","Keep"))))
A33: CLM-GL-2024-0388 | B33: 2024 | C33: General Liability | D33: Premise fall | E33: Open | F33: 9880.55 | G33: 6220.4 | H33: 46019 | I33: N | K33: =IF(OR(UPPER(E33)="VOID",A33=Assumptions!$B$13),FALSE,IF(A33=Assumptions!$B$12,FALSE,IF(H33<>MAXIFS($H$5:$H$45,$A$5:$A$45,A33),FALSE,TRUE))) -> 1 | L33: =IF(K33,G33,0) -> 6220.4 | M33: =IF(A33=Assumptions!$B$10,TRUE,FALSE) -> 0 | N33: =IF(AND(K33,NOT(M33)),G33,0) -> 6220.4 | O33: =IF(AND(K33,M33),G33,0) -> 0 | P33: =IF(OR(UPPER(E33)="VOID",A33=Assumptions!$B$13),"Drop-VOID",IF(A33=Assumptions!$B$12,"Drop-closed",IF(H33<>MAXIFS($H$5:$H$45,$A$5:$A$45,A33),"Drop-dup",IF(M33,"Keep-LL","Keep"))))
A34: CLM-AUTO-2025-0019 | B34: 2025 | C34: Commercial Auto | D34: H. Quinn | E34: Open | F34: 8220.4 | G34: 14640.55 | H34: 46019 | I34: N | K34: =IF(OR(UPPER(E34)="VOID",A34=Assumptions!$B$13),FALSE,IF(A34=Assumptions!$B$12,FALSE,IF(H34<>MAXIFS($H$5:$H$45,$A$5:$A$45,A34),FALSE,TRUE))) -> 1 | L34: =IF(K34,G34,0) -> 14640.55 | M34: =IF(A34=Assumptions!$B$10,TRUE,FALSE) -> 0 | N34: =IF(AND(K34,NOT(M34)),G34,0) -> 14640.55 | O34: =IF(AND(K34,M34),G34,0) -> 0 | P34: =IF(OR(UPPER(E34)="VOID",A34=Assumptions!$B$13),"Drop-VOID",IF(A34=Assumptions!$B$12,"Drop-closed",IF(H34<>MAXIFS($H$5:$H$45,$A$5:$A$45,A34),"Drop-dup",IF(M34,"Keep-LL","Keep"))))
A35: CLM-AUTO-2025-0140 | B35: 2025 | C35: Commercial Auto | D35: I. Delgado | E35: Open | F35: 14880.18 | G35: 19220.4 | H35: 46019 | I35: N | K35: =IF(OR(UPPER(E35)="VOID",A35=Assumptions!$B$13),FALSE,IF(A35=Assumptions!$B$12,FALSE,IF(H35<>MAXIFS($H$5:$H$45,$A$5:$A$45,A35),FALSE,TRUE))) -> 1 | L35: =IF(K35,G35,0) -> 19220.4 | M35: =IF(A35=Assumptions!$B$10,TRUE,FALSE) -> 0 | N35: =IF(AND(K35,NOT(M35)),G35,0) -> 19220.4 | O35: =IF(AND(K35,M35),G35,0) -> 0 | P35: =IF(OR(UPPER(E35)="VOID",A35=Assumptions!$B$13),"Drop-VOID",IF(A35=Assumptions!$B$12,"Drop-closed",IF(H35<>MAXIFS($H$5:$H$45,$A$5:$A$45,A35),"Drop-dup",IF(M35,"Keep-LL","Keep"))))
A36: CLM-AUTO-2025-0277 | B36: 2025 | C36: Commercial Auto | D36: F. Okonkwo | E36: Open | F36: 6640.55 | G36: 11110.22 | H36: 46019 | I36: N | K36: =IF(OR(UPPER(E36)="VOID",A36=Assumptions!$B$13),FALSE,IF(A36=Assumptions!$B$12,FALSE,IF(H36<>MAXIFS($H$5:$H$45,$A$5:$A$45,A36),FALSE,TRUE))) -> 1 | L36: =IF(K36,G36,0) -> 11110.22 | M36: =IF(A36=Assumptions!$B$10,TRUE,FALSE) -> 0 | N36: =IF(AND(K36,NOT(M36)),G36,0) -> 11110.22 | O36: =IF(AND(K36,M36),G36,0) -> 0 | P36: =IF(OR(UPPER(E36)="VOID",A36=Assumptions!$B$13),"Drop-VOID",IF(A36=Assumptions!$B$12,"Drop-closed",IF(H36<>MAXIFS($H$5:$H$45,$A$5:$A$45,A36),"Drop-dup",IF(M36,"Keep-LL","Keep"))))
A37: CLM-AUTO-2025-0391 | B37: 2025 | C37: Commercial Auto | D37: G. Marsh | E37: Open | F37: 21110 | G37: 16880.4 | H37: 46019 | I37: N | K37: =IF(OR(UPPER(E37)="VOID",A37=Assumptions!$B$13),FALSE,IF(A37=Assumptions!$B$12,FALSE,IF(H37<>MAXIFS($H$5:$H$45,$A$5:$A$45,A37),FALSE,TRUE))) -> 1 | L37: =IF(K37,G37,0) -> 16880.4 | M37: =IF(A37=Assumptions!$B$10,TRUE,FALSE) -> 0 | N37: =IF(AND(K37,NOT(M37)),G37,0) -> 16880.4 | O37: =IF(AND(K37,M37),G37,0) -> 0 | P37: =IF(OR(UPPER(E37)="VOID",A37=Assumptions!$B$13),"Drop-VOID",IF(A37=Assumptions!$B$12,"Drop-closed",IF(H37<>MAXIFS($H$5:$H$45,$A$5:$A$45,A37),"Drop-dup",IF(M37,"Keep-LL","Keep"))))
A38: CLM-AUTO-2025-0502 | B38: 2025 | C38: Commercial Auto | D38: Y. Tran | E38: Open | F38: 9420.18 | G38: 9640.55 | H38: 46019 | I38: N | K38: =IF(OR(UPPER(E38)="VOID",A38=Assumptions!$B$13),FALSE,IF(A38=Assumptions!$B$12,FALSE,IF(H38<>MAXIFS($H$5:$H$45,$A$5:$A$45,A38),FALSE,TRUE))) -> 1 | L38: =IF(K38,G38,0) -> 9640.55 | M38: =IF(A38=Assumptions!$B$10,TRUE,FALSE) -> 0 | N38: =IF(AND(K38,NOT(M38)),G38,0) -> 9640.55 | O38: =IF(AND(K38,M38),G38,0) -> 0 | P38: =IF(OR(UPPER(E38)="VOID",A38=Assumptions!$B$13),"Drop-VOID",IF(A38=Assumptions!$B$12,"Drop-closed",IF(H38<>MAXIFS($H$5:$H$45,$A$5:$A$45,A38),"Drop-dup",IF(M38,"Keep-LL","Keep"))))
A39: CLM-GL-2025-0021 | B39: 2025 | C39: General Liability | D39: Visitor injury | E39: Open | F39: 11220.18 | G39: 12640.55 | H39: 46019 | I39: N | K39: =IF(OR(UPPER(E39)="VOID",A39=Assumptions!$B$13),FALSE,IF(A39=Assumptions!$B$12,FALSE,IF(H39<>MAXIFS($H$5:$H$45,$A$5:$A$45,A39),FALSE,TRUE))) -> 1 | L39: =IF(K39,G39,0) -> 12640.55 | M39: =IF(A39=Assumptions!$B$10,TRUE,FALSE) -> 0 | N39: =IF(AND(K39,NOT(M39)),G39,0) -> 12640.55 | O39: =IF(AND(K39,M39),G39,0) -> 0 | P39: =IF(OR(UPPER(E39)="VOID",A39=Assumptions!$B$13),"Drop-VOID",IF(A39=Assumptions!$B$12,"Drop-closed",IF(H39<>MAXIFS($H$5:$H$45,$A$5:$A$45,A39),"Drop-dup",IF(M39,"Keep-LL","Keep"))))
A40: CLM-GL-2025-0088 | B40: 2025 | C40: General Liability | D40: Property damage | E40: Open | F40: 16640.4 | G40: 14110.18 | H40: 46019 | I40: N | K40: =IF(OR(UPPER(E40)="VOID",A40=Assumptions!$B$13),FALSE,IF(A40=Assumptions!$B$12,FALSE,IF(H40<>MAXIFS($H$5:$H$45,$A$5:$A$45,A40),FALSE,TRUE))) -> 1 | L40: =IF(K40,G40,0) -> 14110.18 | M40: =IF(A40=Assumptions!$B$10,TRUE,FALSE) -> 0 | N40: =IF(AND(K40,NOT(M40)),G40,0) -> 14110.18 | O40: =IF(AND(K40,M40),G40,0) -> 0 | P40: =IF(OR(UPPER(E40)="VOID",A40=Assumptions!$B$13),"Drop-VOID",IF(A40=Assumptions!$B$12,"Drop-closed",IF(H40<>MAXIFS($H$5:$H$45,$A$5:$A$45,A40),"Drop-dup",IF(M40,"Keep-LL","Keep"))))
A41: CLM-GL-2025-0144 | B41: 2025 | C41: General Liability | D41: Terminal visitor | E41: Open | F41: 4220.18 | G41: 22400 | H41: 45991 | I41: N | J41: Preliminary case | K41: =IF(OR(UPPER(E41)="VOID",A41=Assumptions!$B$13),FALSE,IF(A41=Assumptions!$B$12,FALSE,IF(H41<>MAXIFS($H$5:$H$45,$A$5:$A$45,A41),FALSE,TRUE))) -> 0 | L41: =IF(K41,G41,0) -> 0 | M41: =IF(A41=Assumptions!$B$10,TRUE,FALSE) -> 0 | N41: =IF(AND(K41,NOT(M41)),G41,0) -> 0 | O41: =IF(AND(K41,M41),G41,0) -> 0 | P41: =IF(OR(UPPER(E41)="VOID",A41=Assumptions!$B$13),"Drop-VOID",IF(A41=Assumptions!$B$12,"Drop-closed",IF(H41<>MAXIFS($H$5:$H$45,$A$5:$A$45,A41),"Drop-dup",IF(M41,"Keep-LL","Keep"))))
...

Sheet AY Development
A1: AY Development
A2: Paid LDFs per actuarial memo; draft factors on Definitions tab are superseded.
A4: AY | B4: Age (mo) | C4: Paid LDF | D4: Gross Paid | E4: LL Paid Carve | F4: Attritional Paid | G4: Attritional Ult | H4: Attritional Case | I4: Pure IBNR | J4: LL Case | K4: LL Ultimate | L4: Indicated Ultimate | M4: Cleaned Case
A5: 2022 | B5: 48 | C5: =IF(B5=12,Assumptions!$B$6,IF(B5=24,Assumptions!$B$7,IF(B5=36,Assumptions!$B$8,Assumptions!$B$9))) -> 1.06 | D5: 412840.55 | E5: =IF(COUNTIFS('Case Inventory'!$A$5:$A$45,Assumptions!$B$10,'Case Inventory'!$B$5:$B$45,A5)>0,Assumptions!$B$11,0) -> 0 | F5: =D5-E5 -> 412840.55 | G5: =ROUND(F5*C5,2) -> 437610.98 | H5: =SUMIFS('Case Inventory'!$N$5:$N$45,'Case Inventory'!$B$5:$B$45,A5) -> 23803.35 | I5: =MAX(0,ROUND(G5-F5-H5,2)) -> 967.08 | J5: =SUMIFS('Case Inventory'!$O$5:$O$45,'Case Inventory'!$B$5:$B$45,A5) -> 0 | K5: =ROUND(E5+J5,2) -> 0 | L5: =ROUND(G5+K5,2) -> 437610.98 | M5: =SUMIFS('Case Inventory'!$L$5:$L$45,'Case Inventory'!$B$5:$B$45,A5) -> 23803.35
A6: 2023 | B6: 36 | C6: =IF(B6=12,Assumptions!$B$6,IF(B6=24,Assumptions!$B$7,IF(B6=36,Assumptions!$B$8,Assumptions!$B$9))) -> 1.18 | D6: 628410.22 | E6: =IF(COUNTIFS('Case Inventory'!$A$5:$A$45,Assumptions!$B$10,'Case Inventory'!$B$5:$B$45,A6)>0,Assumptions!$B$11,0) -> 185220.4 | F6: =D6-E6 -> 443189.82 | G6: =ROUND(F6*C6,2) -> 522963.99 | H6: =SUMIFS('Case Inventory'!$N$5:$N$45,'Case Inventory'!$B$5:$B$45,A6) -> 51683.95 | I6: =MAX(0,ROUND(G6-F6-H6,2)) -> 28090.22 | J6: =SUMIFS('Case Inventory'!$O$5:$O$45,'Case Inventory'!$B$5:$B$45,A6) -> 142880.4 | K6: =ROUND(E6+J6,2) -> 328100.8 | L6: =ROUND(G6+K6,2) -> 851064.79 | M6: =SUMIFS('Case Inventory'!$L$5:$L$45,'Case Inventory'!$B$5:$B$45,A6) -> 194564.35
A7: 2024 | B7: 24 | C7: =IF(B7=12,Assumptions!$B$6,IF(B7=24,Assumptions!$B$7,IF(B7=36,Assumptions!$B$8,Assumptions!$B$9))) -> 1.41 | D7: 391220.18 | E7: =IF(COUNTIFS('Case Inventory'!$A$5:$A$45,Assumptions!$B$10,'Case Inventory'!$B$5:$B$45,A7)>0,Assumptions!$B$11,0) -> 0 | F7: =D7-E7 -> 391220.18 | G7: =ROUND(F7*C7,2) -> 551620.45 | H7: =SUMIFS('Case Inventory'!$N$5:$N$45,'Case Inventory'!$B$5:$B$45,A7) -> 94564.9 | I7: =MAX(0,ROUND(G7-F7-H7,2)) -> 65835.37 | J7: =SUMIFS('Case Inventory'!$O$5:$O$45,'Case Inventory'!$B$5:$B$45,A7) -> 0 | K7: =ROUND(E7+J7,2) -> 0 | L7: =ROUND(G7+K7,2) -> 551620.45 | M7: =SUMIFS('Case Inventory'!$L$5:$L$45,'Case Inventory'!$B$5:$B$45,A7) -> 94564.9
A8: 2025 | B8: 12 | C8: =IF(B8=12,Assumptions!$B$6,IF(B8=24,Assumptions!$B$7,IF(B8=36,Assumptions!$B$8,Assumptions!$B$9))) -> 1.82 | D8: 148640.55 | E8: =IF(COUNTIFS('Case Inventory'!$A$5:$A$45,Assumptions!$B$10,'Case Inventory'!$B$5:$B$45,A8)>0,Assumptions!$B$11,0) -> 0 | F8: =D8-E8 -> 148640.55 | G8: =ROUND(F8*C8,2) -> 270525.8 | H8: =SUMIFS('Case Inventory'!$N$5:$N$45,'Case Inventory'!$B$5:$B$45,A8) -> 147156.4 | I8: =MAX(0,ROUND(G8-F8-H8,2)) -> 0 | J8: =SUMIFS('Case Inventory'!$O$5:$O$45,'Case Inventory'!$B$5:$B$45,A8) -> 0 | K8: =ROUND(E8+J8,2) -> 0 | L8: =ROUND(G8+K8,2) -> 270525.8 | M8: =SUMIFS('Case Inventory'!$L$5:$L$45,'Case Inventory'!$B$5:$B$45,A8) -> 147156.4
A9: TOTAL | D9: =SUM(D5:D8) -> 1581111.5 | E9: =SUM(E5:E8) -> 185220.4 | F9: =SUM(F5:F8) -> 1395891.1 | G9: =SUM(G5:G8) -> 1782721.2 | H9: =SUM(H5:H8) -> 317208.6 | I9: =SUM(I5:I8) -> 94892.67 | J9: =SUM(J5:J8) -> 142880.4 | K9: =SUM(K5:K8) -> 328100.8 | ... M9: =SUM(M5:M8) -> 460089
A11: Note
A12: Large Loss Adjustment — CLM-AUTO-2023-4412: carve paid pre-LDF; LL ult = paid+case.

Sheet Reserve Opinion
A1: Crowhaven Logistics — Reserve Opinion
A2: PKG-CA-GL-IN-2025-4418 | YE 2025-12-31 | Renewal 2026-03-01
A4: Item | B4: Amount
A5: Cleaned Case | B5: ='AY Development'!M9 -> 460089
A6: Pure IBNR | B6: ='AY Development'!I9 -> 94892.67
A7: Total Reserve | B7: =ROUND(B5+B6,2) -> 554981.67
A8: Indicated Ultimate | B8: ='AY Development'!L9 -> 2110822
A9: Earned Premium | B9: =Assumptions!B14 -> 2850220.4
A10: Ultimate LR | B10: =B8/B9 -> 0.740582
A11: Refer Threshold | B11: =Assumptions!B15 -> 0.685
A12: Decline Threshold | B12: =Assumptions!B16 -> 0.85
A13: Prior Booked Reserve | B13: =Assumptions!B17 -> 1104220.2
A15: Large Loss Adjustment
A16: LL Paid Carve | B16: ='AY Development'!E9 -> 185220.4
A17: LL Case | B17: ='AY Development'!J9 -> 142880.4
A18: LL Ultimate | B18: ='AY Development'!K9 -> 328100.8
A20: Tie-out
A21: Cleaned Case (Inventory) | B21: ='Case Inventory'!L46 -> 460089
A22: Case Diff (AY − Inventory) | B22: =ROUND(B5-B21,2) -> 0
A24: Note | B24: Paid LDFs per actuarial memo; draft factors on Definitions tab are superseded.

Sheet UW Recommendation
A1: UW Recommendation — Crowhaven Logistics
A2: PKG-CA-GL-IN-2025-4418 | YE 2025-12-31 | Renewal 2026-03-01
A4: Item | B4: Value
A5: Final Recommendation | B5: Refer
A6: Ultimate LR | B6: ='Reserve Opinion'!B10 -> 0.740582
A7: Refer Threshold | B7: =Assumptions!B15 -> 0.685
A8: Decline Threshold | B8: =Assumptions!B16 -> 0.85
A9: Decision Tie-out | B9: =IF('Reserve Opinion'!B10>Assumptions!B16,"Decline",IF('Reserve Opinion'!B10>Assumptions!B15,"Refer","Quote")) -> Refer
A11: Rationale | B11: 74.06% > 68.5% refer threshold and < 85.0% decline threshold.
A13: Reserve Summary
A14: Cleaned Case | B14: ='Reserve Opinion'!B5 -> 460089
A15: Pure IBNR | B15: ='Reserve Opinion'!B6 -> 94892.67
A16: Total Reserve | B16: ='Reserve Opinion'!B7 -> 554981.67
A17: Indicated Ultimate | B17: ='Reserve Opinion'!B8 -> 2110822
A18: Earned Premium | B18: ='Reserve Opinion'!B9 -> 2850220.4
